[2025-01-29T15:11:47.954+0000] {local_task_job_runner.py:123} INFO - ::group::Pre task execution logs
[2025-01-29T15:11:47.967+0000] {taskinstance.py:2613} INFO - Dependencies all met for dep_context=non-requeueable deps ti=<TaskInstance: save_to_minio.save_to_minio scheduled__2025-01-28T00:00:00+00:00 [queued]>
[2025-01-29T15:11:47.974+0000] {taskinstance.py:2613} INFO - Dependencies all met for dep_context=requeueable deps ti=<TaskInstance: save_to_minio.save_to_minio scheduled__2025-01-28T00:00:00+00:00 [queued]>
[2025-01-29T15:11:47.975+0000] {taskinstance.py:2866} INFO - Starting attempt 5 of 6
[2025-01-29T15:11:47.984+0000] {taskinstance.py:2889} INFO - Executing <Task(PythonOperator): save_to_minio> on 2025-01-28 00:00:00+00:00
[2025-01-29T15:11:47.989+0000] {standard_task_runner.py:72} INFO - Started process 420 to run task
[2025-01-29T15:11:47.991+0000] {standard_task_runner.py:104} INFO - Running: ['***', 'tasks', 'run', 'save_to_minio', 'save_to_minio', 'scheduled__2025-01-28T00:00:00+00:00', '--job-id', '7', '--raw', '--subdir', 'DAGS_FOLDER/main_pipeline.py', '--cfg-path', '/tmp/tmp0rs974vi']
[2025-01-29T15:11:47.994+0000] {standard_task_runner.py:105} INFO - Job 7: Subtask save_to_minio
[2025-01-29T15:11:48.028+0000] {task_command.py:467} INFO - Running <TaskInstance: save_to_minio.save_to_minio scheduled__2025-01-28T00:00:00+00:00 [running]> on host 21ecc35bc506
[2025-01-29T15:11:48.085+0000] {taskinstance.py:3132} INFO - Exporting env vars: AIRFLOW_CTX_DAG_OWNER='andrewsis' AIRFLOW_CTX_DAG_ID='save_to_minio' AIRFLOW_CTX_TASK_ID='save_to_minio' AIRFLOW_CTX_EXECUTION_DATE='2025-01-28T00:00:00+00:00' AIRFLOW_CTX_TRY_NUMBER='5' AIRFLOW_CTX_DAG_RUN_ID='scheduled__2025-01-28T00:00:00+00:00'
[2025-01-29T15:11:48.087+0000] {taskinstance.py:731} INFO - ::endgroup::
[2025-01-29T15:11:50.148+0000] {base.py:84} INFO - Retrieving connection 'minio_conn'
[2025-01-29T15:11:50.149+0000] {connection_wrapper.py:325} INFO - AWS Connection (conn_id='minio_conn', conn_type='aws') credentials retrieved from login and password.
[2025-01-29T15:11:50.812+0000] {taskinstance.py:3311} ERROR - Task failed with exception
Traceback (most recent call last):
  File "/home/airflow/.local/lib/python3.11/site-packages/airflow/models/taskinstance.py", line 767, in _execute_task
    result = _execute_callable(context=context, **execute_callable_kwargs)
             ^^^^^^^^^^^^^^^^^^^^^^^^^^^^^^^^^^^^^^^^^^^^^^^^^^^^^^^^^^^^^
  File "/home/airflow/.local/lib/python3.11/site-packages/airflow/models/taskinstance.py", line 733, in _execute_callable
    return ExecutionCallableRunner(
           ^^^^^^^^^^^^^^^^^^^^^^^^
  File "/home/airflow/.local/lib/python3.11/site-packages/airflow/utils/operator_helpers.py", line 252, in run
    return self.func(*args, **kwargs)
           ^^^^^^^^^^^^^^^^^^^^^^^^^^
  File "/home/airflow/.local/lib/python3.11/site-packages/airflow/models/baseoperator.py", line 422, in wrapper
    return func(self, *args, **kwargs)
           ^^^^^^^^^^^^^^^^^^^^^^^^^^^
  File "/home/airflow/.local/lib/python3.11/site-packages/airflow/operators/python.py", line 238, in execute
    return_value = self.execute_callable()
                   ^^^^^^^^^^^^^^^^^^^^^^^
  File "/home/airflow/.local/lib/python3.11/site-packages/airflow/operators/python.py", line 256, in execute_callable
    return runner.run(*self.op_args, **self.op_kwargs)
           ^^^^^^^^^^^^^^^^^^^^^^^^^^^^^^^^^^^^^^^^^^^
  File "/home/airflow/.local/lib/python3.11/site-packages/airflow/utils/operator_helpers.py", line 252, in run
    return self.func(*args, **kwargs)
           ^^^^^^^^^^^^^^^^^^^^^^^^^^
  File "/opt/airflow/dags/main_pipeline.py", line 25, in save_to_minio
    s3_hook.load_string(
  File "/home/airflow/.local/lib/python3.11/site-packages/airflow/providers/amazon/aws/hooks/s3.py", line 152, in wrapper
    return func(*bound_args.args, **bound_args.kwargs)
           ^^^^^^^^^^^^^^^^^^^^^^^^^^^^^^^^^^^^^^^^^^^
  File "/home/airflow/.local/lib/python3.11/site-packages/airflow/providers/amazon/aws/hooks/s3.py", line 125, in wrapper
    return func(*bound_args.args, **bound_args.kwargs)
           ^^^^^^^^^^^^^^^^^^^^^^^^^^^^^^^^^^^^^^^^^^^
  File "/home/airflow/.local/lib/python3.11/site-packages/airflow/providers/amazon/aws/hooks/s3.py", line 1197, in load_string
    self._upload_file_obj(f, key, bucket_name, replace, encrypt, acl_policy)
  File "/home/airflow/.local/lib/python3.11/site-packages/airflow/providers/amazon/aws/hooks/s3.py", line 1280, in _upload_file_obj
    client.upload_fileobj(
  File "/home/airflow/.local/lib/python3.11/site-packages/boto3/s3/inject.py", line 642, in upload_fileobj
    return future.result()
           ^^^^^^^^^^^^^^^
  File "/home/airflow/.local/lib/python3.11/site-packages/s3transfer/futures.py", line 103, in result
    return self._coordinator.result()
           ^^^^^^^^^^^^^^^^^^^^^^^^^^
  File "/home/airflow/.local/lib/python3.11/site-packages/s3transfer/futures.py", line 264, in result
    raise self._exception
  File "/home/airflow/.local/lib/python3.11/site-packages/s3transfer/tasks.py", line 135, in __call__
    return self._execute_main(kwargs)
           ^^^^^^^^^^^^^^^^^^^^^^^^^^
  File "/home/airflow/.local/lib/python3.11/site-packages/s3transfer/tasks.py", line 158, in _execute_main
    return_value = self._main(**kwargs)
                   ^^^^^^^^^^^^^^^^^^^^
  File "/home/airflow/.local/lib/python3.11/site-packages/s3transfer/upload.py", line 762, in _main
    client.put_object(Bucket=bucket, Key=key, Body=body, **extra_args)
  File "/home/airflow/.local/lib/python3.11/site-packages/botocore/client.py", line 569, in _api_call
    return self._make_api_call(operation_name, kwargs)
           ^^^^^^^^^^^^^^^^^^^^^^^^^^^^^^^^^^^^^^^^^^^
  File "/home/airflow/.local/lib/python3.11/site-packages/botocore/client.py", line 1023, in _make_api_call
    raise error_class(parsed_response, operation_name)
botocore.exceptions.ClientError: An error occurred (InvalidAccessKeyId) when calling the PutObject operation: The AWS Access Key Id you provided does not exist in our records.
[2025-01-29T15:11:50.824+0000] {taskinstance.py:1225} INFO - Marking task as UP_FOR_RETRY. dag_id=save_to_minio, task_id=save_to_minio, run_id=scheduled__2025-01-28T00:00:00+00:00, execution_date=20250128T000000, start_date=20250129T151147, end_date=20250129T151150
[2025-01-29T15:11:50.834+0000] {taskinstance.py:340} INFO - ::group::Post task execution logs
[2025-01-29T15:11:50.835+0000] {standard_task_runner.py:124} ERROR - Failed to execute job 7 for task save_to_minio (An error occurred (InvalidAccessKeyId) when calling the PutObject operation: The AWS Access Key Id you provided does not exist in our records.; 420)
Traceback (most recent call last):
  File "/home/airflow/.local/lib/python3.11/site-packages/airflow/task/task_runner/standard_task_runner.py", line 117, in _start_by_fork
    ret = args.func(args, dag=self.dag)
          ^^^^^^^^^^^^^^^^^^^^^^^^^^^^^
  File "/home/airflow/.local/lib/python3.11/site-packages/airflow/cli/cli_config.py", line 49, in command
    return func(*args, **kwargs)
           ^^^^^^^^^^^^^^^^^^^^^
  File "/home/airflow/.local/lib/python3.11/site-packages/airflow/utils/cli.py", line 116, in wrapper
    return f(*args, **kwargs)
           ^^^^^^^^^^^^^^^^^^
  File "/home/airflow/.local/lib/python3.11/site-packages/airflow/cli/commands/task_command.py", line 483, in task_run
    task_return_code = _run_task_by_selected_method(args, _dag, ti)
                       ^^^^^^^^^^^^^^^^^^^^^^^^^^^^^^^^^^^^^^^^^^^^
  File "/home/airflow/.local/lib/python3.11/site-packages/airflow/cli/commands/task_command.py", line 256, in _run_task_by_selected_method
    return _run_raw_task(args, ti)
           ^^^^^^^^^^^^^^^^^^^^^^^
  File "/home/airflow/.local/lib/python3.11/site-packages/airflow/cli/commands/task_command.py", line 341, in _run_raw_task
    return ti._run_raw_task(
           ^^^^^^^^^^^^^^^^^
  File "/home/airflow/.local/lib/python3.11/site-packages/airflow/utils/session.py", line 97, in wrapper
    return func(*args, session=session, **kwargs)
           ^^^^^^^^^^^^^^^^^^^^^^^^^^^^^^^^^^^^^^
  File "/home/airflow/.local/lib/python3.11/site-packages/airflow/models/taskinstance.py", line 3005, in _run_raw_task
    return _run_raw_task(
           ^^^^^^^^^^^^^^
  File "/home/airflow/.local/lib/python3.11/site-packages/airflow/models/taskinstance.py", line 273, in _run_raw_task
    TaskInstance._execute_task_with_callbacks(
  File "/home/airflow/.local/lib/python3.11/site-packages/airflow/models/taskinstance.py", line 3159, in _execute_task_with_callbacks
    result = self._execute_task(context, task_orig)
             ^^^^^^^^^^^^^^^^^^^^^^^^^^^^^^^^^^^^^^
  File "/home/airflow/.local/lib/python3.11/site-packages/airflow/models/taskinstance.py", line 3183, in _execute_task
    return _execute_task(self, context, task_orig)
           ^^^^^^^^^^^^^^^^^^^^^^^^^^^^^^^^^^^^^^^
  File "/home/airflow/.local/lib/python3.11/site-packages/airflow/models/taskinstance.py", line 767, in _execute_task
    result = _execute_callable(context=context, **execute_callable_kwargs)
             ^^^^^^^^^^^^^^^^^^^^^^^^^^^^^^^^^^^^^^^^^^^^^^^^^^^^^^^^^^^^^
  File "/home/airflow/.local/lib/python3.11/site-packages/airflow/models/taskinstance.py", line 733, in _execute_callable
    return ExecutionCallableRunner(
           ^^^^^^^^^^^^^^^^^^^^^^^^
  File "/home/airflow/.local/lib/python3.11/site-packages/airflow/utils/operator_helpers.py", line 252, in run
    return self.func(*args, **kwargs)
           ^^^^^^^^^^^^^^^^^^^^^^^^^^
  File "/home/airflow/.local/lib/python3.11/site-packages/airflow/models/baseoperator.py", line 422, in wrapper
    return func(self, *args, **kwargs)
           ^^^^^^^^^^^^^^^^^^^^^^^^^^^
  File "/home/airflow/.local/lib/python3.11/site-packages/airflow/operators/python.py", line 238, in execute
    return_value = self.execute_callable()
                   ^^^^^^^^^^^^^^^^^^^^^^^
  File "/home/airflow/.local/lib/python3.11/site-packages/airflow/operators/python.py", line 256, in execute_callable
    return runner.run(*self.op_args, **self.op_kwargs)
           ^^^^^^^^^^^^^^^^^^^^^^^^^^^^^^^^^^^^^^^^^^^
  File "/home/airflow/.local/lib/python3.11/site-packages/airflow/utils/operator_helpers.py", line 252, in run
    return self.func(*args, **kwargs)
           ^^^^^^^^^^^^^^^^^^^^^^^^^^
  File "/opt/airflow/dags/main_pipeline.py", line 25, in save_to_minio
    s3_hook.load_string(
  File "/home/airflow/.local/lib/python3.11/site-packages/airflow/providers/amazon/aws/hooks/s3.py", line 152, in wrapper
    return func(*bound_args.args, **bound_args.kwargs)
           ^^^^^^^^^^^^^^^^^^^^^^^^^^^^^^^^^^^^^^^^^^^
  File "/home/airflow/.local/lib/python3.11/site-packages/airflow/providers/amazon/aws/hooks/s3.py", line 125, in wrapper
    return func(*bound_args.args, **bound_args.kwargs)
           ^^^^^^^^^^^^^^^^^^^^^^^^^^^^^^^^^^^^^^^^^^^
  File "/home/airflow/.local/lib/python3.11/site-packages/airflow/providers/amazon/aws/hooks/s3.py", line 1197, in load_string
    self._upload_file_obj(f, key, bucket_name, replace, encrypt, acl_policy)
  File "/home/airflow/.local/lib/python3.11/site-packages/airflow/providers/amazon/aws/hooks/s3.py", line 1280, in _upload_file_obj
    client.upload_fileobj(
  File "/home/airflow/.local/lib/python3.11/site-packages/boto3/s3/inject.py", line 642, in upload_fileobj
    return future.result()
           ^^^^^^^^^^^^^^^
  File "/home/airflow/.local/lib/python3.11/site-packages/s3transfer/futures.py", line 103, in result
    return self._coordinator.result()
           ^^^^^^^^^^^^^^^^^^^^^^^^^^
  File "/home/airflow/.local/lib/python3.11/site-packages/s3transfer/futures.py", line 264, in result
    raise self._exception
  File "/home/airflow/.local/lib/python3.11/site-packages/s3transfer/tasks.py", line 135, in __call__
    return self._execute_main(kwargs)
           ^^^^^^^^^^^^^^^^^^^^^^^^^^
  File "/home/airflow/.local/lib/python3.11/site-packages/s3transfer/tasks.py", line 158, in _execute_main
    return_value = self._main(**kwargs)
                   ^^^^^^^^^^^^^^^^^^^^
  File "/home/airflow/.local/lib/python3.11/site-packages/s3transfer/upload.py", line 762, in _main
    client.put_object(Bucket=bucket, Key=key, Body=body, **extra_args)
  File "/home/airflow/.local/lib/python3.11/site-packages/botocore/client.py", line 569, in _api_call
    return self._make_api_call(operation_name, kwargs)
           ^^^^^^^^^^^^^^^^^^^^^^^^^^^^^^^^^^^^^^^^^^^
  File "/home/airflow/.local/lib/python3.11/site-packages/botocore/client.py", line 1023, in _make_api_call
    raise error_class(parsed_response, operation_name)
botocore.exceptions.ClientError: An error occurred (InvalidAccessKeyId) when calling the PutObject operation: The AWS Access Key Id you provided does not exist in our records.
[2025-01-29T15:11:50.854+0000] {local_task_job_runner.py:266} INFO - Task exited with return code 1
[2025-01-29T15:11:50.869+0000] {taskinstance.py:3895} INFO - 0 downstream tasks scheduled from follow-on schedule check
[2025-01-29T15:11:50.871+0000] {local_task_job_runner.py:245} INFO - ::endgroup::
