[2025-02-01T19:15:54.768+0000] {local_task_job_runner.py:123} INFO - ::group::Pre task execution logs
[2025-02-01T19:15:54.781+0000] {taskinstance.py:2613} INFO - Dependencies all met for dep_context=non-requeueable deps ti=<TaskInstance: save_to_minio.save_to_minio scheduled__2025-01-31T00:00:00+00:00 [queued]>
[2025-02-01T19:15:54.788+0000] {taskinstance.py:2613} INFO - Dependencies all met for dep_context=requeueable deps ti=<TaskInstance: save_to_minio.save_to_minio scheduled__2025-01-31T00:00:00+00:00 [queued]>
[2025-02-01T19:15:54.789+0000] {taskinstance.py:2866} INFO - Starting attempt 2 of 7
[2025-02-01T19:15:54.798+0000] {taskinstance.py:2889} INFO - Executing <Task(PythonOperator): save_to_minio> on 2025-01-31 00:00:00+00:00
[2025-02-01T19:15:54.802+0000] {standard_task_runner.py:72} INFO - Started process 1066 to run task
[2025-02-01T19:15:54.804+0000] {standard_task_runner.py:104} INFO - Running: ['***', 'tasks', 'run', 'save_to_minio', 'save_to_minio', 'scheduled__2025-01-31T00:00:00+00:00', '--job-id', '8', '--raw', '--subdir', 'DAGS_FOLDER/main_pipeline.py', '--cfg-path', '/tmp/tmpu6g4gpuo']
[2025-02-01T19:15:54.807+0000] {standard_task_runner.py:105} INFO - Job 8: Subtask save_to_minio
[2025-02-01T19:15:54.842+0000] {task_command.py:467} INFO - Running <TaskInstance: save_to_minio.save_to_minio scheduled__2025-01-31T00:00:00+00:00 [running]> on host 30dcbc5a0039
[2025-02-01T19:15:54.898+0000] {taskinstance.py:3132} INFO - Exporting env vars: AIRFLOW_CTX_DAG_OWNER='andrewsis' AIRFLOW_CTX_DAG_ID='save_to_minio' AIRFLOW_CTX_TASK_ID='save_to_minio' AIRFLOW_CTX_EXECUTION_DATE='2025-01-31T00:00:00+00:00' AIRFLOW_CTX_TRY_NUMBER='2' AIRFLOW_CTX_DAG_RUN_ID='scheduled__2025-01-31T00:00:00+00:00'
[2025-02-01T19:15:54.899+0000] {taskinstance.py:731} INFO - ::endgroup::
[2025-02-01T19:15:57.702+0000] {base.py:84} INFO - Retrieving connection 'minio_conn'
[2025-02-01T19:15:57.703+0000] {connection_wrapper.py:325} INFO - AWS Connection (conn_id='minio_conn', conn_type='aws') credentials retrieved from login and password.
[2025-02-01T19:15:58.089+0000] {taskinstance.py:3311} ERROR - Task failed with exception
Traceback (most recent call last):
  File "/home/airflow/.local/lib/python3.11/site-packages/airflow/models/taskinstance.py", line 767, in _execute_task
    result = _execute_callable(context=context, **execute_callable_kwargs)
             ^^^^^^^^^^^^^^^^^^^^^^^^^^^^^^^^^^^^^^^^^^^^^^^^^^^^^^^^^^^^^
  File "/home/airflow/.local/lib/python3.11/site-packages/airflow/models/taskinstance.py", line 733, in _execute_callable
    return ExecutionCallableRunner(
           ^^^^^^^^^^^^^^^^^^^^^^^^
  File "/home/airflow/.local/lib/python3.11/site-packages/airflow/utils/operator_helpers.py", line 252, in run
    return self.func(*args, **kwargs)
           ^^^^^^^^^^^^^^^^^^^^^^^^^^
  File "/home/airflow/.local/lib/python3.11/site-packages/airflow/models/baseoperator.py", line 422, in wrapper
    return func(self, *args, **kwargs)
           ^^^^^^^^^^^^^^^^^^^^^^^^^^^
  File "/home/airflow/.local/lib/python3.11/site-packages/airflow/operators/python.py", line 238, in execute
    return_value = self.execute_callable()
                   ^^^^^^^^^^^^^^^^^^^^^^^
  File "/home/airflow/.local/lib/python3.11/site-packages/airflow/operators/python.py", line 256, in execute_callable
    return runner.run(*self.op_args, **self.op_kwargs)
           ^^^^^^^^^^^^^^^^^^^^^^^^^^^^^^^^^^^^^^^^^^^
  File "/home/airflow/.local/lib/python3.11/site-packages/airflow/utils/operator_helpers.py", line 252, in run
    return self.func(*args, **kwargs)
           ^^^^^^^^^^^^^^^^^^^^^^^^^^
  File "/opt/airflow/dags/main_pipeline.py", line 25, in save_to_minio
    s3_hook.load_string(
  File "/home/airflow/.local/lib/python3.11/site-packages/airflow/providers/amazon/aws/hooks/s3.py", line 152, in wrapper
    return func(*bound_args.args, **bound_args.kwargs)
           ^^^^^^^^^^^^^^^^^^^^^^^^^^^^^^^^^^^^^^^^^^^
  File "/home/airflow/.local/lib/python3.11/site-packages/airflow/providers/amazon/aws/hooks/s3.py", line 125, in wrapper
    return func(*bound_args.args, **bound_args.kwargs)
           ^^^^^^^^^^^^^^^^^^^^^^^^^^^^^^^^^^^^^^^^^^^
  File "/home/airflow/.local/lib/python3.11/site-packages/airflow/providers/amazon/aws/hooks/s3.py", line 1197, in load_string
    self._upload_file_obj(f, key, bucket_name, replace, encrypt, acl_policy)
  File "/home/airflow/.local/lib/python3.11/site-packages/airflow/providers/amazon/aws/hooks/s3.py", line 1280, in _upload_file_obj
    client.upload_fileobj(
  File "/home/airflow/.local/lib/python3.11/site-packages/boto3/s3/inject.py", line 642, in upload_fileobj
    return future.result()
           ^^^^^^^^^^^^^^^
  File "/home/airflow/.local/lib/python3.11/site-packages/s3transfer/futures.py", line 103, in result
    return self._coordinator.result()
           ^^^^^^^^^^^^^^^^^^^^^^^^^^
  File "/home/airflow/.local/lib/python3.11/site-packages/s3transfer/futures.py", line 264, in result
    raise self._exception
  File "/home/airflow/.local/lib/python3.11/site-packages/s3transfer/tasks.py", line 135, in __call__
    return self._execute_main(kwargs)
           ^^^^^^^^^^^^^^^^^^^^^^^^^^
  File "/home/airflow/.local/lib/python3.11/site-packages/s3transfer/tasks.py", line 158, in _execute_main
    return_value = self._main(**kwargs)
                   ^^^^^^^^^^^^^^^^^^^^
  File "/home/airflow/.local/lib/python3.11/site-packages/s3transfer/upload.py", line 762, in _main
    client.put_object(Bucket=bucket, Key=key, Body=body, **extra_args)
  File "/home/airflow/.local/lib/python3.11/site-packages/botocore/client.py", line 569, in _api_call
    return self._make_api_call(operation_name, kwargs)
           ^^^^^^^^^^^^^^^^^^^^^^^^^^^^^^^^^^^^^^^^^^^
  File "/home/airflow/.local/lib/python3.11/site-packages/botocore/client.py", line 1023, in _make_api_call
    raise error_class(parsed_response, operation_name)
botocore.errorfactory.NoSuchBucket: An error occurred (NoSuchBucket) when calling the PutObject operation: The specified bucket does not exist
[2025-02-01T19:15:58.099+0000] {taskinstance.py:1225} INFO - Marking task as UP_FOR_RETRY. dag_id=save_to_minio, task_id=save_to_minio, run_id=scheduled__2025-01-31T00:00:00+00:00, execution_date=20250131T000000, start_date=20250201T191554, end_date=20250201T191558
[2025-02-01T19:15:58.109+0000] {taskinstance.py:340} INFO - ::group::Post task execution logs
[2025-02-01T19:15:58.110+0000] {standard_task_runner.py:124} ERROR - Failed to execute job 8 for task save_to_minio (An error occurred (NoSuchBucket) when calling the PutObject operation: The specified bucket does not exist; 1066)
Traceback (most recent call last):
  File "/home/airflow/.local/lib/python3.11/site-packages/airflow/task/task_runner/standard_task_runner.py", line 117, in _start_by_fork
    ret = args.func(args, dag=self.dag)
          ^^^^^^^^^^^^^^^^^^^^^^^^^^^^^
  File "/home/airflow/.local/lib/python3.11/site-packages/airflow/cli/cli_config.py", line 49, in command
    return func(*args, **kwargs)
           ^^^^^^^^^^^^^^^^^^^^^
  File "/home/airflow/.local/lib/python3.11/site-packages/airflow/utils/cli.py", line 116, in wrapper
    return f(*args, **kwargs)
           ^^^^^^^^^^^^^^^^^^
  File "/home/airflow/.local/lib/python3.11/site-packages/airflow/cli/commands/task_command.py", line 483, in task_run
    task_return_code = _run_task_by_selected_method(args, _dag, ti)
                       ^^^^^^^^^^^^^^^^^^^^^^^^^^^^^^^^^^^^^^^^^^^^
  File "/home/airflow/.local/lib/python3.11/site-packages/airflow/cli/commands/task_command.py", line 256, in _run_task_by_selected_method
    return _run_raw_task(args, ti)
           ^^^^^^^^^^^^^^^^^^^^^^^
  File "/home/airflow/.local/lib/python3.11/site-packages/airflow/cli/commands/task_command.py", line 341, in _run_raw_task
    return ti._run_raw_task(
           ^^^^^^^^^^^^^^^^^
  File "/home/airflow/.local/lib/python3.11/site-packages/airflow/utils/session.py", line 97, in wrapper
    return func(*args, session=session, **kwargs)
           ^^^^^^^^^^^^^^^^^^^^^^^^^^^^^^^^^^^^^^
  File "/home/airflow/.local/lib/python3.11/site-packages/airflow/models/taskinstance.py", line 3005, in _run_raw_task
    return _run_raw_task(
           ^^^^^^^^^^^^^^
  File "/home/airflow/.local/lib/python3.11/site-packages/airflow/models/taskinstance.py", line 273, in _run_raw_task
    TaskInstance._execute_task_with_callbacks(
  File "/home/airflow/.local/lib/python3.11/site-packages/airflow/models/taskinstance.py", line 3159, in _execute_task_with_callbacks
    result = self._execute_task(context, task_orig)
             ^^^^^^^^^^^^^^^^^^^^^^^^^^^^^^^^^^^^^^
  File "/home/airflow/.local/lib/python3.11/site-packages/airflow/models/taskinstance.py", line 3183, in _execute_task
    return _execute_task(self, context, task_orig)
           ^^^^^^^^^^^^^^^^^^^^^^^^^^^^^^^^^^^^^^^
  File "/home/airflow/.local/lib/python3.11/site-packages/airflow/models/taskinstance.py", line 767, in _execute_task
    result = _execute_callable(context=context, **execute_callable_kwargs)
             ^^^^^^^^^^^^^^^^^^^^^^^^^^^^^^^^^^^^^^^^^^^^^^^^^^^^^^^^^^^^^
  File "/home/airflow/.local/lib/python3.11/site-packages/airflow/models/taskinstance.py", line 733, in _execute_callable
    return ExecutionCallableRunner(
           ^^^^^^^^^^^^^^^^^^^^^^^^
  File "/home/airflow/.local/lib/python3.11/site-packages/airflow/utils/operator_helpers.py", line 252, in run
    return self.func(*args, **kwargs)
           ^^^^^^^^^^^^^^^^^^^^^^^^^^
  File "/home/airflow/.local/lib/python3.11/site-packages/airflow/models/baseoperator.py", line 422, in wrapper
    return func(self, *args, **kwargs)
           ^^^^^^^^^^^^^^^^^^^^^^^^^^^
  File "/home/airflow/.local/lib/python3.11/site-packages/airflow/operators/python.py", line 238, in execute
    return_value = self.execute_callable()
                   ^^^^^^^^^^^^^^^^^^^^^^^
  File "/home/airflow/.local/lib/python3.11/site-packages/airflow/operators/python.py", line 256, in execute_callable
    return runner.run(*self.op_args, **self.op_kwargs)
           ^^^^^^^^^^^^^^^^^^^^^^^^^^^^^^^^^^^^^^^^^^^
  File "/home/airflow/.local/lib/python3.11/site-packages/airflow/utils/operator_helpers.py", line 252, in run
    return self.func(*args, **kwargs)
           ^^^^^^^^^^^^^^^^^^^^^^^^^^
  File "/opt/airflow/dags/main_pipeline.py", line 25, in save_to_minio
    s3_hook.load_string(
  File "/home/airflow/.local/lib/python3.11/site-packages/airflow/providers/amazon/aws/hooks/s3.py", line 152, in wrapper
    return func(*bound_args.args, **bound_args.kwargs)
           ^^^^^^^^^^^^^^^^^^^^^^^^^^^^^^^^^^^^^^^^^^^
  File "/home/airflow/.local/lib/python3.11/site-packages/airflow/providers/amazon/aws/hooks/s3.py", line 125, in wrapper
    return func(*bound_args.args, **bound_args.kwargs)
           ^^^^^^^^^^^^^^^^^^^^^^^^^^^^^^^^^^^^^^^^^^^
  File "/home/airflow/.local/lib/python3.11/site-packages/airflow/providers/amazon/aws/hooks/s3.py", line 1197, in load_string
    self._upload_file_obj(f, key, bucket_name, replace, encrypt, acl_policy)
  File "/home/airflow/.local/lib/python3.11/site-packages/airflow/providers/amazon/aws/hooks/s3.py", line 1280, in _upload_file_obj
    client.upload_fileobj(
  File "/home/airflow/.local/lib/python3.11/site-packages/boto3/s3/inject.py", line 642, in upload_fileobj
    return future.result()
           ^^^^^^^^^^^^^^^
  File "/home/airflow/.local/lib/python3.11/site-packages/s3transfer/futures.py", line 103, in result
    return self._coordinator.result()
           ^^^^^^^^^^^^^^^^^^^^^^^^^^
  File "/home/airflow/.local/lib/python3.11/site-packages/s3transfer/futures.py", line 264, in result
    raise self._exception
  File "/home/airflow/.local/lib/python3.11/site-packages/s3transfer/tasks.py", line 135, in __call__
    return self._execute_main(kwargs)
           ^^^^^^^^^^^^^^^^^^^^^^^^^^
  File "/home/airflow/.local/lib/python3.11/site-packages/s3transfer/tasks.py", line 158, in _execute_main
    return_value = self._main(**kwargs)
                   ^^^^^^^^^^^^^^^^^^^^
  File "/home/airflow/.local/lib/python3.11/site-packages/s3transfer/upload.py", line 762, in _main
    client.put_object(Bucket=bucket, Key=key, Body=body, **extra_args)
  File "/home/airflow/.local/lib/python3.11/site-packages/botocore/client.py", line 569, in _api_call
    return self._make_api_call(operation_name, kwargs)
           ^^^^^^^^^^^^^^^^^^^^^^^^^^^^^^^^^^^^^^^^^^^
  File "/home/airflow/.local/lib/python3.11/site-packages/botocore/client.py", line 1023, in _make_api_call
    raise error_class(parsed_response, operation_name)
botocore.errorfactory.NoSuchBucket: An error occurred (NoSuchBucket) when calling the PutObject operation: The specified bucket does not exist
[2025-02-01T19:15:58.149+0000] {local_task_job_runner.py:266} INFO - Task exited with return code 1
[2025-02-01T19:15:58.167+0000] {taskinstance.py:3895} INFO - 0 downstream tasks scheduled from follow-on schedule check
[2025-02-01T19:15:58.169+0000] {local_task_job_runner.py:245} INFO - ::endgroup::
[2025-02-01T22:03:28.913+0000] {local_task_job_runner.py:123} INFO - ::group::Pre task execution logs
[2025-02-01T22:03:28.927+0000] {taskinstance.py:2613} INFO - Dependencies all met for dep_context=non-requeueable deps ti=<TaskInstance: save_to_minio.save_to_minio scheduled__2025-01-31T00:00:00+00:00 [queued]>
[2025-02-01T22:03:28.939+0000] {taskinstance.py:2613} INFO - Dependencies all met for dep_context=requeueable deps ti=<TaskInstance: save_to_minio.save_to_minio scheduled__2025-01-31T00:00:00+00:00 [queued]>
[2025-02-01T22:03:28.940+0000] {taskinstance.py:2866} INFO - Starting attempt 2 of 7
[2025-02-01T22:03:28.955+0000] {taskinstance.py:2889} INFO - Executing <Task(PythonOperator): save_to_minio> on 2025-01-31 00:00:00+00:00
[2025-02-01T22:03:28.962+0000] {standard_task_runner.py:72} INFO - Started process 2665 to run task
[2025-02-01T22:03:28.964+0000] {standard_task_runner.py:104} INFO - Running: ['***', 'tasks', 'run', 'save_to_minio', 'save_to_minio', 'scheduled__2025-01-31T00:00:00+00:00', '--job-id', '18', '--raw', '--subdir', 'DAGS_FOLDER/main_pipeline.py', '--cfg-path', '/tmp/tmpjg2ptsm2']
[2025-02-01T22:03:28.967+0000] {standard_task_runner.py:105} INFO - Job 18: Subtask save_to_minio
[2025-02-01T22:03:29.008+0000] {task_command.py:467} INFO - Running <TaskInstance: save_to_minio.save_to_minio scheduled__2025-01-31T00:00:00+00:00 [running]> on host 2f541c1544a4
[2025-02-01T22:03:29.073+0000] {taskinstance.py:3132} INFO - Exporting env vars: AIRFLOW_CTX_DAG_OWNER='andrewsis' AIRFLOW_CTX_DAG_ID='save_to_minio' AIRFLOW_CTX_TASK_ID='save_to_minio' AIRFLOW_CTX_EXECUTION_DATE='2025-01-31T00:00:00+00:00' AIRFLOW_CTX_TRY_NUMBER='2' AIRFLOW_CTX_DAG_RUN_ID='scheduled__2025-01-31T00:00:00+00:00'
[2025-02-01T22:03:29.074+0000] {taskinstance.py:731} INFO - ::endgroup::
[2025-02-01T22:03:31.182+0000] {base.py:84} INFO - Retrieving connection 'minio_conn'
[2025-02-01T22:03:31.184+0000] {connection_wrapper.py:325} INFO - AWS Connection (conn_id='minio_conn', conn_type='aws') credentials retrieved from login and password.
[2025-02-01T22:03:31.770+0000] {python.py:240} INFO - Done. Returned value was: None
[2025-02-01T22:03:31.779+0000] {taskinstance.py:340} INFO - ::group::Post task execution logs
[2025-02-01T22:03:31.780+0000] {taskinstance.py:352} INFO - Marking task as SUCCESS. dag_id=save_to_minio, task_id=save_to_minio, run_id=scheduled__2025-01-31T00:00:00+00:00, execution_date=20250131T000000, start_date=20250201T220328, end_date=20250201T220331
[2025-02-01T22:03:31.828+0000] {local_task_job_runner.py:266} INFO - Task exited with return code 0
[2025-02-01T22:03:31.848+0000] {taskinstance.py:3895} INFO - 1 downstream tasks scheduled from follow-on schedule check
[2025-02-01T22:03:31.850+0000] {local_task_job_runner.py:245} INFO - ::endgroup::
